Workbook

Sheet Balance Sheet
A1: CANADIAN IMPERIAL BANK OF COMMERCE
A2: CIBC 2025 Annual Report
A3: Consolidated Balance Sheet
A5: ($ millions, as at October 31) | B5: 2025 | C5: 2024 | D5: YoY Change
A6: ASSETS
A7: Cash and non-interest-bearing deposits with banks | B7: 12379 | C7: 8565 | D7: =IF(C7=0,"-",B7/C7-1) -> 0.44530064
A8: Interest-bearing deposits with banks | B8: 31624 | C8: 39499 | D8: =IF(C8=0,"-",B8/C8-1) -> -0.19937214
A9: Securities | B9: 283235 | C9: 254345 | D9: =IF(C9=0,"-",B9/C9-1) -> 0.11358588
A10: Cash collateral on securities borrowed | B10: 21697 | C10: 17028 | D10: =IF(C10=0,"-",B10/C10-1) -> 0.27419544
A11: Securities purchased under resale agreements | B11: 86695 | C11: 83721 | D11: =IF(C11=0,"-",B11/C11-1) -> 0.035522748
A13: Loans
A14: Residential mortgages | B14: 287033 | C14: 280672 | D14: =IF(C14=0,"-",B14/C14-1) -> 0.022663465
A15: Personal | B15: 47866 | C15: 46681 | D15: =IF(C15=0,"-",B15/C15-1) -> 0.02538506
A16: Credit card | B16: 21581 | C16: 20551 | D16: =IF(C16=0,"-",B16/C16-1) -> 0.050119216
A17: Business and government | B17: 237416 | C17: 214305 | D17: =IF(C17=0,"-",B17/C17-1) -> 0.10784163
A18: Allowance for credit losses | B18: -4392 | C18: -3917 | D18: =IF(C18=0,"-",B18/C18-1) -> 0.12126628
A19: Total net loans | B19: 589504 | C19: 558292 | D19: =IF(C19=0,"-",B19/C19-1) -> 0.055906228
A21: Other Assets
A22: Derivative instruments | B22: 38352 | C22: 36435 | D22: =IF(C22=0,"-",B22/C22-1) -> 0.052614245
A23: Property and equipment | B23: 3443 | C23: 3359 | D23: =IF(C23=0,"-",B23/C23-1) -> 0.025007443
A24: Goodwill | B24: 5475 | C24: 5443 | D24: =IF(C24=0,"-",B24/C24-1) -> 0.0058791108
A25: Software and other intangible assets | B25: 2894 | C25: 2830 | D25: =IF(C25=0,"-",B25/C25-1) -> 0.022614841
A26: Investments in equity-accounted associates and JVs | B26: 808 | C26: 785 | D26: =IF(C26=0,"-",B26/C26-1) -> 0.029299363
A27: Deferred tax assets | B27: 1027 | C27: 821 | D27: =IF(C27=0,"-",B27/C27-1) -> 0.25091352
A28: Other assets | B28: 39805 | C28: 30862 | D28: =IF(C28=0,"-",B28/C28-1) -> 0.28977383
A29: Total other assets | B29: 91804 | C29: 80535 | D29: =IF(C29=0,"-",B29/C29-1) -> 0.13992674
A31: TOTAL ASSETS | B31: 1116938 | C31: 1041985 | D31: =IF(C31=0,"-",B31/C31-1) -> 0.071932897
A33: LIABILITIES AND EQUITY
A34: Deposits
A35: Personal | B35: 258139 | C35: 252894 | D35: =IF(C35=0,"-",B35/C35-1) -> 0.020739915
A36: Business and government | B36: 457284 | C36: 435499 | D36: =IF(C36=0,"-",B36/C36-1) -> 0.050023077
A37: Bank | B37: 26723 | C37: 20009 | D37: =IF(C37=0,"-",B37/C37-1) -> 0.335549
A38: Secured borrowings | B38: 65978 | C38: 56455 | D38: =IF(C38=0,"-",B38/C38-1) -> 0.16868302
A39: Total deposits | B39: 808124 | C39: 764857 | D39: =IF(C39=0,"-",B39/C39-1) -> 0.056568744
A41: Obligations related to securities sold short | B41: 24244 | C41: 21642 | D41: =IF(C41=0,"-",B41/C41-1) -> 0.12022918
A42: Cash collateral on securities lent | B42: 6031 | C42: 7997 | D42: =IF(C42=0,"-",B42/C42-1) -> -0.24584219
A43: Obligations related to securities sold under repo agreements | B43: 130042 | C43: 110153 | D43: =IF(C43=0,"-",B43/C43-1) -> 0.18055795
A45: Other Liabilities
A46: Derivative instruments | B46: 41411 | C46: 40654 | D46: =IF(C46=0,"-",B46/C46-1) -> 0.018620554
A47: Deferred tax liabilities | B47: 47 | C47: 49 | D47: =IF(C47=0,"-",B47/C47-1) -> -0.040816327
...

Sheet Income Statement
A1: CANADIAN IMPERIAL BANK OF COMMERCE
A2: CIBC 2025 Annual Report
A3: Consolidated Statement of Income
A5: ($ millions, for the year ended October 31) | B5: 2025 | C5: 2024 | D5: YoY Change
A6: INTEREST INCOME
A7: Loans | B7: 32074 | C7: 33925 | D7: =IF(C7=0,"-",B7/C7-1) -> -0.054561533
A8: Securities | B8: 9045 | C8: 9560 | D8: =IF(C8=0,"-",B8/C8-1) -> -0.053870293
A9: Securities borrowed or purchased under resale agreements | B9: 5260 | C9: 5811 | D9: =IF(C9=0,"-",B9/C9-1) -> -0.094820169
A10: Deposits with banks and other | B10: 2382 | C10: 2889 | D10: =IF(C10=0,"-",B10/C10-1) -> -0.17549325
A11: Total interest income | B11: 48761 | C11: 52185 | D11: =IF(C11=0,"-",B11/C11-1) -> -0.065612724
A13: INTEREST EXPENSE
A14: Deposits | B14: 25110 | C14: 30476 | D14: =IF(C14=0,"-",B14/C14-1) -> -0.17607298
A15: Securities sold short | B15: 565 | C15: 625 | D15: =IF(C15=0,"-",B15/C15-1) -> -0.096
A16: Securities lent or sold under repurchase agreements | B16: 6521 | C16: 6334 | D16: =IF(C16=0,"-",B16/C16-1) -> 0.029523208
A17: Subordinated indebtedness | B17: 407 | C17: 510 | D17: =IF(C17=0,"-",B17/C17-1) -> -0.20196078
A18: Other | B18: 389 | C18: 545 | D18: =IF(C18=0,"-",B18/C18-1) -> -0.28623853
A19: Total interest expense | B19: 32992 | C19: 38490 | D19: =IF(C19=0,"-",B19/C19-1) -> -0.1428423
A21: NET INTEREST INCOME | B21: 15769 | C21: 13695 | D21: =IF(C21=0,"-",B21/C21-1) -> 0.15144213
A23: NON-INTEREST INCOME
A24: Underwriting and advisory fees | B24: 915 | C24: 707 | D24: =IF(C24=0,"-",B24/C24-1) -> 0.29420085
A25: Deposit and payment fees | B25: 996 | C25: 958 | D25: =IF(C25=0,"-",B25/C25-1) -> 0.039665971
A26: Credit fees | B26: 1015 | C26: 1218 | D26: =IF(C26=0,"-",B26/C26-1) -> -0.16666667
A27: Card fees | B27: 402 | C27: 414 | D27: =IF(C27=0,"-",B27/C27-1) -> -0.028985507
A28: Investment management and custodial fees | B28: 2241 | C28: 1980 | D28: =IF(C28=0,"-",B28/C28-1) -> 0.13181818
A29: Mutual fund fees | B29: 2019 | C29: 1796 | D29: =IF(C29=0,"-",B29/C29-1) -> 0.12416481
A30: Income from insurance activities, net | B30: 317 | C30: 356 | D30: =IF(C30=0,"-",B30/C30-1) -> -0.10955056
A31: Commissions on securities transactions | B31: 554 | C31: 431 | D31: =IF(C31=0,"-",B31/C31-1) -> 0.28538283
A32: Gains (losses) from instruments at FVTPL, net | B32: 4022 | C32: 3226 | D32: =IF(C32=0,"-",B32/C32-1) -> 0.2467452
A33: Gains (losses) from debt securities at FVOCI & amort. cost | B33: -14 | C33: 43 | D33: =IF(C33=0,"-",B33/C33-1) -> -1.3255814
A34: Foreign exchange other than trading | B34: 369 | C34: 386 | D34: =IF(C34=0,"-",B34/C34-1) -> -0.044041451
A35: Income from equity-accounted associates and JVs | B35: 117 | C35: 79 | D35: =IF(C35=0,"-",B35/C35-1) -> 0.48101266
... A41: Provision for credit losses | B41: 2342 | C41: 2001 | D41: =IF(C41=0,"-",B41/C41-1) -> 0.17041479
A43: NON-INTEREST EXPENSES
A44: Employee compensation and benefits | B44: 9266 | C44: 8261 | D44: =IF(C44=0,"-",B44/C44-1) -> 0.12165597
A45: Occupancy costs | B45: 847 | C45: 830 | D45: =IF(C45=0,"-",B45/C45-1) -> 0.020481928
A46: Computer, software and office equipment | B46: 2946 | C46: 2719 | D46: =IF(C46=0,"-",B46/C46-1) -> 0.083486576
A47: Communications | B47: 395 | C47: 362 | D47: =IF(C47=0,"-",B47/C47-1) -> 0.091160221
A48: Advertising and business development | B48: 398 | C48: 344 | D48: =IF(C48=0,"-",B48/C48-1) -> 0.15697674
A49: Professional fees | B49: 284 | C49: 257 | D49: =IF(C49=0,"-",B49/C49-1) -> 0.10505837
A50: Business and capital taxes | B50: 124 | C50: 128 | D50: =IF(C50=0,"-",B50/C50-1) -> -0.03125
...

Sheet Cash Flows
A1: CANADIAN IMPERIAL BANK OF COMMERCE
A2: CIBC 2025 Annual Report
A3: Consolidated Statement of Cash Flows
A5: ($ millions, for the year ended October 31) | B5: 2025 | C5: 2024
A6: OPERATING ACTIVITIES
A7: Net income | B7: 8454 | C7: 7154
A8: Provision for credit losses | B8: 2342 | C8: 2001
A9: Amortization and impairment | B9: 1178 | C9: 1170
A10: Deferred income taxes | B10: -257 | C10: -244
A11: Net changes in operating assets and liabilities:
A12: Interest-bearing deposits with banks | B12: 7875 | C12: -4597
A13: Loans, net of repayments | B13: -33381 | C13: -28930
A14: Deposits, net of withdrawals | B14: 37183 | C14: 34467
A15: Derivative assets | B15: -1921 | C15: -3240
A16: Derivative liabilities | B16: 328 | C16: -813
A17: Securities measured at FVTPL | B17: -22817 | C17: -23319
A18: Obligations related to securities sold under repo | B18: 19889 | C18: 23035
A19: Other, net | B19: -1706 | C19: 6361
A20: Net cash from operating activities | B20: 13838 | C20: 11088
A22: FINANCING ACTIVITIES
A23: Issue of subordinated indebtedness | B23: 1250 | C23: 2250
A24: Redemption/repurchase of subordinated indebtedness | B24: -1069 | C24: -1536
A25: Issue of preferred shares and LRCNs | B25: 2757 | C25: 996
A26: Redemption of preferred shares and LRCNs | B26: -1350 | C26: -975
A27: Issue of common shares for cash | B27: 158 | C27: 312
A28: Purchase of common shares for cancellation | B28: -1731 | C28: -419
A29: Dividends and distributions paid | B29: -3993 | C29: -2947
A30: Repayment of lease liabilities | B30: -309 | C30: -287
A31: Other, net | B31: -29 | C31: 0
A32: Net cash from financing activities | B32: -4312 | C32: -2610
A34: INVESTING ACTIVITIES
A35: Purchase of securities at FVOCI and amortized cost | B35: -98369 | C35: -76528
A36: Proceeds from sale of securities at FVOCI/amort. cost | B36: 46299 | C36: 29761
A37: Proceeds from maturity of debt securities | B37: 47404 | C37: 27105
A38: Net sale (purchase) of property, equipment, software | B38: -1109 | C38: -1089
A39: Net cash from investing activities | B39: -5775 | C39: -20751
A41: Effect of exchange rate changes | B41: 63 | C41: 22
A42: Net increase (decrease) in cash | B42: 3814 | C42: -12251
A43: Cash at beginning of year | B43: 8565 | C43: 20816
A44: Cash at end of year | B44: 12379 | C44: 8565
...

Sheet Key Ratios
A1: CANADIAN IMPERIAL BANK OF COMMERCE
A2: CIBC 2025 Annual Report
A3: Key Financial Ratios & KPIs
A5: Metric | B5: 2025 | C5: 2024 | D5: Change
A6: PROFITABILITY
A7: Net Income ($M) | B7: ='Income Statement'!B56 -> 8454 | C7: ='Income Statement'!C56 -> 7154 | D7: =IF(C7=0,"-",B7/C7-1) -> 0.18171652
A8: Total Revenue ($M) | B8: ='Income Statement'!B39 -> 29133 | C8: ='Income Statement'!C39 -> 25606 | D8: =IF(C8=0,"-",B8/C8-1) -> 0.13774115
A9: Net Interest Income ($M) | B9: ='Income Statement'!B21 -> 15769 | C9: ='Income Statement'!C21 -> 13695 | D9: =IF(C9=0,"-",B9/C9-1) -> 0.15144213
A10: Non-Interest Income ($M) | B10: ='Income Statement'!B37 -> 13364 | C10: ='Income Statement'!C37 -> 11911 | D10: =IF(C10=0,"-",B10/C10-1) -> 0.12198808
A11: Basic EPS ($) | B11: ='Income Statement'!B64 -> 8.62 | C11: ='Income Statement'!C64 -> 7.29 | D11: =IF(C11=0,"-",B11/C11-1) -> 0.1824417
A12: Diluted EPS ($) | B12: ='Income Statement'!B65 -> 8.57 | C12: ='Income Statement'!C65 -> 7.28 | D12: =IF(C12=0,"-",B12/C12-1) -> 0.1771978
A13: Dividends per Share ($) | B13: ='Income Statement'!B66 -> 3.88 | C13: ='Income Statement'!C66 -> 3.6 | D13: =IF(C13=0,"-",B13/C13-1) -> 0.077777778
A15: EFFICIENCY & MARGINS
A16: Net Interest Margin (NII / Avg Assets) | B16: ='Income Statement'!B21/'Balance Sheet'!B31 -> 0.014118062 | C16: ='Income Statement'!C21/'Balance Sheet'!C31 -> 0.013143183
A17: Efficiency Ratio (NIE / Revenue) | B17: ='Income Statement'!B52/'Income Statement'!B39 -> 0.54412522 | C17: ='Income Statement'!C52/'Income Statement'!C39 -> 0.56389128
A18: Provision for Credit Losses ($M) | B18: ='Income Statement'!B41 -> 2342 | C18: ='Income Statement'!C41 -> 2001 | D18: =IF(C18=0,"-",B18/C18-1) -> 0.17041479
A19: PCL / Total Loans | B19: ='Income Statement'!B41/'Balance Sheet'!B19 -> 0.0039728314 | C19: ='Income Statement'!C41/'Balance Sheet'!C19 -> 0.0035841459
A20: Effective Tax Rate | B20: ='Income Statement'!B55/'Income Statement'!B54 -> 0.22716885 | C20: ='Income Statement'!C55/'Income Statement'!C54 -> 0.21950687
A22: CAPITAL & LEVERAGE
A23: CET1 Capital ($M) | B23: 47718 | C23: 44516 | D23: =IF(C23=0,"-",B23/C23-1) -> 0.071929194
A24: Tier 1 Capital ($M) | B24: 54105 | C24: 49481 | D24: =IF(C24=0,"-",B24/C24-1) -> 0.093450011
A25: Total Capital ($M) | B25: 62287 | C25: 56809 | D25: =IF(C25=0,"-",B25/C25-1) -> 0.096428383
A26: Total RWA ($M) | B26: 357803 | C26: 333502 | D26: =IF(C26=0,"-",B26/C26-1) -> 0.07286613
A27: CET1 Ratio | B27: 0.133 | C27: 0.133 | D27: =IF(C27=0,"-",B27/C27-1) -> 0
A28: Tier 1 Capital Ratio | B28: 0.151 | C28: 0.148 | D28: =IF(C28=0,"-",B28/C28-1) -> 0.02027027
A29: Total Capital Ratio | B29: 0.174 | C29: 0.17 | D29: =IF(C29=0,"-",B29/C29-1) -> 0.023529412
A30: Leverage Ratio | B30: 0.043 | C30: 0.043 | D30: =IF(C30=0,"-",B30/C30-1) -> 0
A31: TLAC Ratio | B31: 0.319 | C31: 0.303 | D31: =IF(C31=0,"-",B31/C31-1) -> 0.052805281
A33: BALANCE SHEET COMPOSITION
A34: Total Assets ($M) | B34: ='Balance Sheet'!B31 -> 1116938 | C34: ='Balance Sheet'!C31 -> 1041985 | D34: =IF(C34=0,"-",B34/C34-1) -> 0.071932897
A35: Total Loans (Gross, $M) | B35: ='Balance Sheet'!B31 -> 1116938 | C35: ='Balance Sheet'!C31 -> 1041985
A36: Total Deposits ($M) | B36: 593896 | C36: 562209 | D36: =IF(C36=0,"-",B36/C36-1) -> 0.056361602
A37: Total Equity ($M) | B37: ='Balance Sheet'!B39 -> 808124 | C37: ='Balance Sheet'!C39 -> 764857 | D37: =IF(C37=0,"-",B37/C37-1) -> 0.056568744
A38: Loan-to-Deposit Ratio | B38: ='Balance Sheet'!B62 -> 64413 | C38: ='Balance Sheet'!C62 -> 59007
B39: =B36/B37 -> 0.73490702 | C39: =C36/C37 -> 0.73505113
A40: CREDIT QUALITY
A41: Allowance for Credit Losses ($M) | B41: 4392 | C41: 3917 | D41: =IF(C41=0,"-",B41/C41-1) -> 0.12126628
A42: Stage 3 ECL ($M) | B42: 982 | C42: 816 | D42: =IF(C42=0,"-",B42/C42-1) -> 0.20343137
A43: Total ECL ($M) | B43: 4739 | C43: 4114 | D43: =IF(C43=0,"-",B43/C43-1) -> 0.15192027
A44: ACL as % of Gross Loans | B44: 0.007 | C44: 0.007 | D44: =IF(C44=0,"-",B44/C44-1) -> 0
...

Sheet Segments
A1: CANADIAN IMPERIAL BANK OF COMMERCE
A2: CIBC 2025 Annual Report
A3: Segmented Information (Power BI Ready)
A5: Year | B5: Segment | C5: Total Revenue | D5: PCL | E5: Net Income | F5: Average Assets | G5: NIE
A6: 2025 | B6: Canadian Personal and Business Banking | C6: 12031 | D6: 1764 | E6: 3107 | F6: 339909 | G6: 6067
A7: 2025 | B7: Canadian Commercial Banking and Wealth Management | C7: 6902 | D7: 166 | E7: 2341 | F7: 103855 | G7: 3522
A8: 2025 | B8: U.S. Commercial Banking and Wealth Management | C8: 3216 | D8: 175 | E8: 958 | F8: 64415 | G8: 1861
A9: 2025 | B9: Capital Markets | C9: 6148 | D9: 208 | E9: 2273 | F9: 378541 | G9: 2855
A10: 2025 | B10: Corporate and Other | C10: 836 | D10: 29 | E10: -225 | F10: 217565 | G10: 1547
A11: 2024 | B11: Canadian Personal and Business Banking | C11: 10942 | D11: 1233 | E11: 2905 | F11: 333793 | G11: 5706
A12: 2024 | B12: Canadian Commercial Banking and Wealth Management | C12: 6018 | D12: 123 | E12: 2063 | F12: 95536 | G12: 3066
A13: 2024 | B13: U.S. Commercial Banking and Wealth Management | C13: 2820 | D13: 560 | E13: 500 | F13: 60820 | G13: 1718
A14: 2024 | B14: Capital Markets | C14: 4800 | D14: 84 | E14: 1629 | F14: 315314 | G14: 2479
A15: 2024 | B15: Corporate and Other | C15: 1026 | D15: 1 | E15: 57 | F15: 199670 | G15: 1470

Sheet Geography
A1: CANADIAN IMPERIAL BANK OF COMMERCE
A2: CIBC 2025 Annual Report
A3: Geographic Information (Power BI Ready)
A5: Year | B5: Region | C5: Total Revenue | D5: Net Income | E5: Average Assets | F5: Income Taxes
A6: 2025 | B6: Canada | C6: 19273 | D6: 3946 | E6: 835506 | F6: 1290
A7: 2025 | B7: U.S. | C7: 5932 | D7: 2216 | E7: 189079 | F7: 754
A8: 2025 | B8: Caribbean | C8: 2726 | D8: 1784 | E8: 55069 | F8: 232
A9: 2025 | B9: Other Countries | C9: 1202 | D9: 508 | E9: 24631 | F9: 209
A10: 2024 | B10: Canada | C10: 17344 | D10: 3621 | E10: 750500 | F10: 1284
A11: 2024 | B11: U.S. | C11: 4834 | D11: 1400 | E11: 177688 | F11: 422
A12: 2024 | B12: Caribbean | C12: 2491 | D12: 1694 | E12: 52862 | F12: 125
A13: 2024 | B13: Other Countries | C13: 937 | D13: 439 | E13: 24083 | F13: 181

Sheet Loan Portfolio
A1: CANADIAN IMPERIAL BANK OF COMMERCE
A2: CIBC 2025 Annual Report
A3: Loan Portfolio by Stage (Power BI Ready)
A5: Year | B5: Loan Type | C5: Gross Amount | D5: Stage 1 | E5: Stage 2 | F5: Stage 3 | G5: Total ACL | H5: ACL %
A6: 2025 | B6: Residential Mortgages | C6: 287033 | D6: 272458 | E6: 13260 | F6: 1315 | G6: 574 | H6: 0.002
A7: 2025 | B7: Personal | C7: 47866 | D7: 41554 | E7: 6022 | F7: 290 | G7: 1156 | H7: 0.024
A8: 2025 | B8: Credit Card | C8: 21581 | D8: 19485 | E8: 2096 | F8: 0 | G8: 942 | H8: 0.044
A9: 2025 | B9: Business and Government | C9: 237416 | D9: 221790 | E9: 13595 | F9: 2031 | G9: 1720 | H9: 0.007
A10: 2024 | B10: Residential Mortgages | C10: 280672 | D10: 255657 | E10: 24021 | F10: 994 | G10: 449 | H10: 0.002
A11: 2024 | B11: Personal | C11: 46681 | D11: 41967 | E11: 4422 | F11: 292 | G11: 942 | H11: 0.02
A12: 2024 | B12: Credit Card | C12: 20551 | D12: 18507 | E12: 2044 | F12: 0 | G12: 902 | H12: 0.044
A13: 2024 | B13: Business and Government | C13: 214305 | D13: 199195 | E13: 13482 | F13: 1628 | G13: 1624 | H13: 0.008

Sheet Deposits
A1: CANADIAN IMPERIAL BANK OF COMMERCE
A2: CIBC 2025 Annual Report
A3: Deposit Breakdown (Power BI Ready)
A5: Year | B5: Deposit Type | C5: Payable on Demand | D5: Payable After Notice | E5: Payable Fixed Date | F5: Total
A6: 2025 | B6: Personal | C6: 15185 | D6: 145592 | E6: 97362 | F6: 258139
A7: 2025 | B7: Business and Government | C7: 109376 | D7: 128092 | E7: 219816 | F7: 457284
A8: 2025 | B8: Bank | C8: 17649 | D8: 337 | E8: 8737 | F8: 26723
A9: 2025 | B9: Secured Borrowings | C9: 0 | D9: 0 | E9: 65978 | F9: 65978
A10: 2024 | B10: Personal | F10: 252894
A11: 2024 | B11: Business and Government | F11: 435499
A12: 2024 | B12: Bank | F12: 20009
A13: 2024 | B13: Secured Borrowings | F13: 56455

Sheet Capital
A1: CANADIAN IMPERIAL BANK OF COMMERCE
A2: CIBC 2025 Annual Report
A3: Capital Adequacy & Regulatory Ratios
A5: ($ millions, as at October 31) | B5: 2025 | C5: 2024 | D5: Regulatory Minimum
A6: CAPITAL COMPOSITION
A7: CET1 Capital | B7: 47718 | C7: 44516
A8: Tier 1 Capital | B8: 54105 | C8: 49481
A9: Total Capital | B9: 62287 | C9: 56809
A10: Total RWA | B10: 357803 | C10: 333502
A12: CAPITAL RATIOS
A13: CET1 Ratio | B13: 0.133 | C13: 0.133 | D13: 0.115
A14: Tier 1 Capital Ratio | B14: 0.151 | C14: 0.148 | D14: 0.13
A15: Total Capital Ratio | B15: 0.174 | C15: 0.17 | D15: 0.15
A17: LEVERAGE
A18: Leverage Ratio Exposure | B18: 1261098 | C18: 1155432
A19: Leverage Ratio | B19: 0.043 | C19: 0.043 | D19: 0.035
A21: TLAC
A22: TLAC Available | B22: 114102 | C22: 101062
A23: TLAC Ratio | B23: 0.319 | C23: 0.303 | D23: 0.25
A24: TLAC Leverage Ratio | B24: 0.09 | C24: 0.087 | D24: 0.0725

Sheet Changes in Equity
A1: CANADIAN IMPERIAL BANK OF COMMERCE
A2: CIBC 2025 Annual Report
A3: Consolidated Statement of Changes in Equity
A5: ($ millions, for the year ended October 31) | B5: 2025 | C5: 2024
A6: PREFERRED SHARES & OTHER EQUITY
A7: Balance at beginning of year | B7: 4946 | C7: 4925
A8: Issue of preferred shares and LRCNs | B8: 2770 | C8: 1000
A9: Redemption of preferred shares and LRCNs | B9: -1350 | C9: -975
A10: Treasury shares | B10: 3 | C10: -4
A11: Balance at end of year | B11: 6369 | C11: 4946
A13: COMMON SHARES
A14: Balance at beginning of year | B14: 17011 | C14: 16082
A15: Issue of common shares | B15: 168 | C15: 1019
A16: Purchase of common shares for cancellation | B16: -335 | C16: -90
A17: Treasury shares | B17: 1 | C17: 0
A18: Balance at end of year | B18: 16845 | C18: 17011
A20: RETAINED EARNINGS
A21: Balance at beginning of year | B21: 33471 | C21: 30352
A22: Net income attributable to equity shareholders | B22: 8429 | C22: 7115
A23: Dividends - preferred and other equity instruments | B23: -364 | C23: -263
A24: Dividends - common | B24: -3629 | C24: -3382
A25: Premium on purchase of common shares for cancellation | B25: -1396 | C25: -329
A26: Other | B26: -40 | C26: -22
A27: Balance at end of year | B27: 36471 | C27: 33471
A29: TOTAL AOCI (net of tax) | B29: 4218 | C29: 3148
A30: Non-controlling interests | B30: 284 | C30: 272
A31: TOTAL EQUITY | B31: 64413 | C31: 59007
